[2022-07-29 00:02:31,871] {taskinstance.py:1159} INFO - Dependencies all met for <TaskInstance: my_dag.dataperf manual__2022-07-29T04:02:30+00:00 [queued]>
[2022-07-29 00:02:31,875] {taskinstance.py:1159} INFO - Dependencies all met for <TaskInstance: my_dag.dataperf manual__2022-07-29T04:02:30+00:00 [queued]>
[2022-07-29 00:02:31,875] {taskinstance.py:1356} INFO - 
--------------------------------------------------------------------------------
[2022-07-29 00:02:31,875] {taskinstance.py:1357} INFO - Starting attempt 1 of 1
[2022-07-29 00:02:31,875] {taskinstance.py:1358} INFO - 
--------------------------------------------------------------------------------
[2022-07-29 00:02:31,891] {taskinstance.py:1377} INFO - Executing <Task(BashOperator): dataperf> on 2022-07-29 04:02:30+00:00
[2022-07-29 00:02:31,892] {standard_task_runner.py:52} INFO - Started process 31714 to run task
[2022-07-29 00:02:31,894] {standard_task_runner.py:79} INFO - Running: ['airflow', 'tasks', 'run', 'my_dag', 'dataperf', 'manual__2022-07-29T04:02:30+00:00', '--job-id', '62', '--raw', '--subdir', 'DAGS_FOLDER/mydag.py', '--cfg-path', '/tmp/tmpdkouq5no', '--error-file', '/tmp/tmpmotu8eq3']
[2022-07-29 00:02:31,894] {standard_task_runner.py:80} INFO - Job 62: Subtask dataperf
[2022-07-29 00:02:31,923] {task_command.py:370} INFO - Running <TaskInstance: my_dag.dataperf manual__2022-07-29T04:02:30+00:00 [running]> on host DESKTOP-5GAFI6N.localdomain
[2022-07-29 00:02:31,963] {taskinstance.py:1569} INFO - Exporting the following env vars:
AIRFLOW_CTX_DAG_OWNER=airflow
AIRFLOW_CTX_DAG_ID=my_dag
AIRFLOW_CTX_TASK_ID=dataperf
AIRFLOW_CTX_EXECUTION_DATE=2022-07-29T04:02:30+00:00
AIRFLOW_CTX_TRY_NUMBER=1
AIRFLOW_CTX_DAG_RUN_ID=manual__2022-07-29T04:02:30+00:00
[2022-07-29 00:02:31,964] {subprocess.py:62} INFO - Tmp dir root location: 
 /tmp
[2022-07-29 00:02:31,964] {subprocess.py:74} INFO - Running command: ['bash', '-c', '\n\ncd /home/lemon/main/Assignment4/dataperf-vision-debugging\nsource .venv/bin/activate\npython3 create_baselines.py && python3 main.py && python3 plotter.py\n']
[2022-07-29 00:02:31,968] {subprocess.py:85} INFO - Output:
[2022-07-29 00:02:33,204] {subprocess.py:92} INFO - Fitting neighbor_shapley (datascope) on 01g317-flipped
[2022-07-29 00:02:33,204] {subprocess.py:92} INFO -  - took 0.05105657300009625 seconds
[2022-07-29 00:02:33,204] {subprocess.py:92} INFO - Fitting random on 01g317-flipped
[2022-07-29 00:02:33,204] {subprocess.py:92} INFO -  - took 9.352799861517269e-05 seconds
[2022-07-29 00:02:35,281] {subprocess.py:92} INFO - On task [01g317-flipped]: Accuracy before cleaning: 0.72
[2022-07-29 00:03:32,531] {local_task_job.py:220} WARNING - State of this instance has been externally set to success. Terminating instance.
[2022-07-29 00:03:32,533] {process_utils.py:125} INFO - Sending Signals.SIGTERM to group 31714. PIDs of all processes in the group: [31715, 31788, 31714]
[2022-07-29 00:03:32,533] {process_utils.py:80} INFO - Sending the signal Signals.SIGTERM to group 31714
[2022-07-29 00:03:32,534] {taskinstance.py:1541} ERROR - Received SIGTERM. Terminating subprocesses.
[2022-07-29 00:03:32,534] {subprocess.py:103} INFO - Sending SIGTERM signal to process group
[2022-07-29 00:03:32,560] {process_utils.py:75} INFO - Process psutil.Process(pid=31714, status='terminated', exitcode=0, started='00:02:31') (31714) terminated with exit code 0
[2022-07-29 00:03:32,560] {process_utils.py:75} INFO - Process psutil.Process(pid=31715, status='terminated', started='00:02:31') (31715) terminated with exit code None
[2022-07-29 00:03:32,561] {process_utils.py:75} INFO - Process psutil.Process(pid=31788, status='terminated', started='00:02:33') (31788) terminated with exit code None
