[2022-07-28 22:26:12,509] {taskinstance.py:1159} INFO - Dependencies all met for <TaskInstance: my_dag.dataperf manual__2022-07-29T02:26:10.513099+00:00 [queued]>
[2022-07-28 22:26:12,513] {taskinstance.py:1159} INFO - Dependencies all met for <TaskInstance: my_dag.dataperf manual__2022-07-29T02:26:10.513099+00:00 [queued]>
[2022-07-28 22:26:12,514] {taskinstance.py:1356} INFO - 
--------------------------------------------------------------------------------
[2022-07-28 22:26:12,514] {taskinstance.py:1357} INFO - Starting attempt 1 of 1
[2022-07-28 22:26:12,514] {taskinstance.py:1358} INFO - 
--------------------------------------------------------------------------------
[2022-07-28 22:26:12,525] {taskinstance.py:1377} INFO - Executing <Task(BashOperator): dataperf> on 2022-07-29 02:26:10.513099+00:00
[2022-07-28 22:26:12,526] {standard_task_runner.py:52} INFO - Started process 22836 to run task
[2022-07-28 22:26:12,529] {standard_task_runner.py:79} INFO - Running: ['airflow', 'tasks', 'run', 'my_dag', 'dataperf', 'manual__2022-07-29T02:26:10.513099+00:00', '--job-id', '55', '--raw', '--subdir', 'DAGS_FOLDER/mydag.py', '--cfg-path', '/tmp/tmpq5ep08nd', '--error-file', '/tmp/tmptyi1_0se']
[2022-07-28 22:26:12,529] {standard_task_runner.py:80} INFO - Job 55: Subtask dataperf
[2022-07-28 22:26:12,563] {task_command.py:370} INFO - Running <TaskInstance: my_dag.dataperf manual__2022-07-29T02:26:10.513099+00:00 [running]> on host DESKTOP-5GAFI6N.localdomain
[2022-07-28 22:26:12,599] {taskinstance.py:1569} INFO - Exporting the following env vars:
AIRFLOW_CTX_DAG_OWNER=airflow
AIRFLOW_CTX_DAG_ID=my_dag
AIRFLOW_CTX_TASK_ID=dataperf
AIRFLOW_CTX_EXECUTION_DATE=2022-07-29T02:26:10.513099+00:00
AIRFLOW_CTX_TRY_NUMBER=1
AIRFLOW_CTX_DAG_RUN_ID=manual__2022-07-29T02:26:10.513099+00:00
[2022-07-28 22:26:12,600] {subprocess.py:62} INFO - Tmp dir root location: 
 /tmp
[2022-07-28 22:26:12,600] {subprocess.py:74} INFO - Running command: ['bash', '-c', '\n\ncd /home/lemon/main/Assignment4/dataperf-vision-debugging\nsource .venv/bin/activate\npython3 create_baselines.py && main.py && plotter.py\n']
[2022-07-28 22:26:12,603] {subprocess.py:85} INFO - Output:
[2022-07-28 22:26:13,778] {subprocess.py:92} INFO - Fitting neighbor_shapley (datascope) on 01g317-flipped
[2022-07-28 22:26:13,779] {subprocess.py:92} INFO -  - took 0.05283546099963132 seconds
[2022-07-28 22:26:13,779] {subprocess.py:92} INFO - Fitting random on 01g317-flipped
[2022-07-28 22:26:13,779] {subprocess.py:92} INFO -  - took 0.00018740799896477256 seconds
[2022-07-28 22:26:14,108] {subprocess.py:92} INFO - bash: line 4: main.py: command not found
[2022-07-28 22:26:14,108] {subprocess.py:96} INFO - Command exited with return code 127
[2022-07-28 22:26:14,115] {taskinstance.py:1889} ERROR - Task failed with exception
Traceback (most recent call last):
  File "/home/lemon/airflow/airflowenv/lib/python3.8/site-packages/airflow/operators/bash.py", line 194, in execute
    raise AirflowException(
airflow.exceptions.AirflowException: Bash command failed. The command returned a non-zero exit code 127.
[2022-07-28 22:26:14,117] {taskinstance.py:1395} INFO - Marking task as FAILED. dag_id=my_dag, task_id=dataperf, execution_date=20220729T022610, start_date=20220729T022612, end_date=20220729T022614
[2022-07-28 22:26:14,127] {standard_task_runner.py:92} ERROR - Failed to execute job 55 for task dataperf (Bash command failed. The command returned a non-zero exit code 127.; 22836)
[2022-07-28 22:26:14,146] {local_task_job.py:156} INFO - Task exited with return code 1
[2022-07-28 22:26:14,171] {local_task_job.py:273} INFO - 0 downstream tasks scheduled from follow-on schedule check
