[2022-07-28 22:05:28,986] {taskinstance.py:1159} INFO - Dependencies all met for <TaskInstance: my_dag.dataperf manual__2022-07-29T02:05:27.732671+00:00 [queued]>
[2022-07-28 22:05:28,990] {taskinstance.py:1159} INFO - Dependencies all met for <TaskInstance: my_dag.dataperf manual__2022-07-29T02:05:27.732671+00:00 [queued]>
[2022-07-28 22:05:28,991] {taskinstance.py:1356} INFO - 
--------------------------------------------------------------------------------
[2022-07-28 22:05:28,991] {taskinstance.py:1357} INFO - Starting attempt 1 of 1
[2022-07-28 22:05:28,991] {taskinstance.py:1358} INFO - 
--------------------------------------------------------------------------------
[2022-07-28 22:05:29,006] {taskinstance.py:1377} INFO - Executing <Task(BashOperator): dataperf> on 2022-07-29 02:05:27.732671+00:00
[2022-07-28 22:05:29,007] {standard_task_runner.py:52} INFO - Started process 18739 to run task
[2022-07-28 22:05:29,009] {standard_task_runner.py:79} INFO - Running: ['airflow', 'tasks', 'run', 'my_dag', 'dataperf', 'manual__2022-07-29T02:05:27.732671+00:00', '--job-id', '47', '--raw', '--subdir', 'DAGS_FOLDER/mydag.py', '--cfg-path', '/tmp/tmpgzjg08te', '--error-file', '/tmp/tmpjf34urzc']
[2022-07-28 22:05:29,009] {standard_task_runner.py:80} INFO - Job 47: Subtask dataperf
[2022-07-28 22:05:29,047] {task_command.py:370} INFO - Running <TaskInstance: my_dag.dataperf manual__2022-07-29T02:05:27.732671+00:00 [running]> on host DESKTOP-5GAFI6N.localdomain
[2022-07-28 22:05:29,087] {taskinstance.py:1569} INFO - Exporting the following env vars:
AIRFLOW_CTX_DAG_OWNER=airflow
AIRFLOW_CTX_DAG_ID=my_dag
AIRFLOW_CTX_TASK_ID=dataperf
AIRFLOW_CTX_EXECUTION_DATE=2022-07-29T02:05:27.732671+00:00
AIRFLOW_CTX_TRY_NUMBER=1
AIRFLOW_CTX_DAG_RUN_ID=manual__2022-07-29T02:05:27.732671+00:00
[2022-07-28 22:05:29,087] {subprocess.py:62} INFO - Tmp dir root location: 
 /tmp
[2022-07-28 22:05:29,088] {subprocess.py:74} INFO - Running command: ['bash', '-c', 'source /home/lemon/main/Assignment4/dataperf-vision-debugging/.venv/bin/activate && python3 /home/lemon/main/Assignment4/dataperf-vision-debugging/create_baselines.py && python3 /home/lemon/main/Assignment4/dataperf-vision-debugging/main.py && python3 /home/lemon/main/Assignment4/dataperf-vision-debugging/plotter.py']
[2022-07-28 22:05:29,092] {subprocess.py:85} INFO - Output:
[2022-07-28 22:05:30,410] {subprocess.py:92} INFO - Traceback (most recent call last):
[2022-07-28 22:05:30,410] {subprocess.py:92} INFO -   File "/home/lemon/main/Assignment4/dataperf-vision-debugging/create_baselines.py", line 9, in <module>
[2022-07-28 22:05:30,410] {subprocess.py:92} INFO -     from baselines.datascope_wrapper import ShapleyAppraiser
[2022-07-28 22:05:30,410] {subprocess.py:92} INFO -   File "/home/lemon/main/Assignment4/dataperf-vision-debugging/baselines/datascope_wrapper.py", line 6, in <module>
[2022-07-28 22:05:30,410] {subprocess.py:92} INFO -     from classifier import XGBClassifier as Classifier
[2022-07-28 22:05:30,410] {subprocess.py:92} INFO -   File "/home/lemon/main/Assignment4/dataperf-vision-debugging/classifier.py", line 4, in <module>
[2022-07-28 22:05:30,411] {subprocess.py:92} INFO -     import xgboost
[2022-07-28 22:05:30,411] {subprocess.py:92} INFO - ModuleNotFoundError: No module named 'xgboost'
[2022-07-28 22:05:30,737] {subprocess.py:96} INFO - Command exited with return code 1
[2022-07-28 22:05:30,744] {taskinstance.py:1889} ERROR - Task failed with exception
Traceback (most recent call last):
  File "/home/lemon/airflow/airflowenv/lib/python3.8/site-packages/airflow/operators/bash.py", line 194, in execute
    raise AirflowException(
airflow.exceptions.AirflowException: Bash command failed. The command returned a non-zero exit code 1.
[2022-07-28 22:05:30,748] {taskinstance.py:1395} INFO - Marking task as FAILED. dag_id=my_dag, task_id=dataperf, execution_date=20220729T020527, start_date=20220729T020528, end_date=20220729T020530
[2022-07-28 22:05:30,763] {standard_task_runner.py:92} ERROR - Failed to execute job 47 for task dataperf (Bash command failed. The command returned a non-zero exit code 1.; 18739)
[2022-07-28 22:05:30,787] {local_task_job.py:156} INFO - Task exited with return code 1
[2022-07-28 22:05:30,813] {local_task_job.py:273} INFO - 0 downstream tasks scheduled from follow-on schedule check
